[2024-04-11T16:47:49.083+0000] {local_task_job_runner.py:120} INFO - ::group::Pre task execution logs
[2024-04-11T16:47:49.223+0000] {taskinstance.py:2073} INFO - Dependencies all met for dep_context=non-requeueable deps ti=<TaskInstance: 22655381_DAG2.process_data scheduled__2024-04-11T16:46:00+00:00 [queued]>
[2024-04-11T16:47:49.227+0000] {taskinstance.py:2073} INFO - Dependencies all met for dep_context=requeueable deps ti=<TaskInstance: 22655381_DAG2.process_data scheduled__2024-04-11T16:46:00+00:00 [queued]>
[2024-04-11T16:47:49.227+0000] {taskinstance.py:2303} INFO - Starting attempt 1 of 2
[2024-04-11T16:47:49.232+0000] {taskinstance.py:2327} INFO - Executing <Task(PythonOperator): process_data> on 2024-04-11 16:46:00+00:00
[2024-04-11T16:47:49.245+0000] {logging_mixin.py:188} WARNING - /home/***/.local/lib/python3.12/site-packages/***/task/task_runner/standard_task_runner.py:61 DeprecationWarning: This process (pid=1780) is multi-threaded, use of fork() may lead to deadlocks in the child.
[2024-04-11T16:47:49.246+0000] {standard_task_runner.py:63} INFO - Started process 1782 to run task
[2024-04-11T16:47:49.245+0000] {standard_task_runner.py:90} INFO - Running: ['***', 'tasks', 'run', '22655381_DAG2', 'process_data', 'scheduled__2024-04-11T16:46:00+00:00', '--job-id', '4', '--raw', '--subdir', 'DAGS_FOLDER/dag_exercise.py', '--cfg-path', '/tmp/tmp8u8592yz']
[2024-04-11T16:47:49.247+0000] {standard_task_runner.py:91} INFO - Job 4: Subtask process_data
[2024-04-11T16:47:49.282+0000] {task_command.py:426} INFO - Running <TaskInstance: 22655381_DAG2.process_data scheduled__2024-04-11T16:46:00+00:00 [running]> on host 51938eebcb2b
[2024-04-11T16:47:49.323+0000] {taskinstance.py:2644} INFO - Exporting env vars: AIRFLOW_CTX_DAG_OWNER='Le Van Duy' AIRFLOW_CTX_DAG_ID='22655381_DAG2' AIRFLOW_CTX_TASK_ID='process_data' AIRFLOW_CTX_EXECUTION_DATE='2024-04-11T16:46:00+00:00' AIRFLOW_CTX_TRY_NUMBER='1' AIRFLOW_CTX_DAG_RUN_ID='scheduled__2024-04-11T16:46:00+00:00'
[2024-04-11T16:47:49.323+0000] {taskinstance.py:430} INFO - ::endgroup::
[2024-04-11T16:47:49.325+0000] {taskinstance.py:441} INFO - ::group::Post task execution logs
[2024-04-11T16:47:49.325+0000] {taskinstance.py:2890} ERROR - Task failed with exception
Traceback (most recent call last):
  File "/home/airflow/.local/lib/python3.12/site-packages/airflow/models/taskinstance.py", line 465, in _execute_task
    result = _execute_callable(context=context, **execute_callable_kwargs)
             ^^^^^^^^^^^^^^^^^^^^^^^^^^^^^^^^^^^^^^^^^^^^^^^^^^^^^^^^^^^^^
  File "/home/airflow/.local/lib/python3.12/site-packages/airflow/models/taskinstance.py", line 432, in _execute_callable
    return execute_callable(context=context, **execute_callable_kwargs)
           ^^^^^^^^^^^^^^^^^^^^^^^^^^^^^^^^^^^^^^^^^^^^^^^^^^^^^^^^^^^^
  File "/home/airflow/.local/lib/python3.12/site-packages/airflow/models/baseoperator.py", line 400, in wrapper
    return func(self, *args, **kwargs)
           ^^^^^^^^^^^^^^^^^^^^^^^^^^^
  File "/home/airflow/.local/lib/python3.12/site-packages/airflow/operators/python.py", line 235, in execute
    return_value = self.execute_callable()
                   ^^^^^^^^^^^^^^^^^^^^^^^
  File "/home/airflow/.local/lib/python3.12/site-packages/airflow/operators/python.py", line 252, in execute_callable
    return self.python_callable(*self.op_args, **self.op_kwargs)
           ^^^^^^^^^^^^^^^^^^^^^^^^^^^^^^^^^^^^^^^^^^^^^^^^^^^^^
  File "/opt/airflow/dags/dag_exercise.py", line 26, in process_data
    df = pd.read_csv('online_retail.csv')
         ^^^^^^^^^^^^^^^^^^^^^^^^^^^^^^^^
  File "/home/airflow/.local/lib/python3.12/site-packages/pandas/io/parsers/readers.py", line 948, in read_csv
    return _read(filepath_or_buffer, kwds)
           ^^^^^^^^^^^^^^^^^^^^^^^^^^^^^^^
  File "/home/airflow/.local/lib/python3.12/site-packages/pandas/io/parsers/readers.py", line 611, in _read
    parser = TextFileReader(filepath_or_buffer, **kwds)
             ^^^^^^^^^^^^^^^^^^^^^^^^^^^^^^^^^^^^^^^^^^
  File "/home/airflow/.local/lib/python3.12/site-packages/pandas/io/parsers/readers.py", line 1448, in __init__
    self._engine = self._make_engine(f, self.engine)
                   ^^^^^^^^^^^^^^^^^^^^^^^^^^^^^^^^^
  File "/home/airflow/.local/lib/python3.12/site-packages/pandas/io/parsers/readers.py", line 1705, in _make_engine
    self.handles = get_handle(
                   ^^^^^^^^^^^
  File "/home/airflow/.local/lib/python3.12/site-packages/pandas/io/common.py", line 863, in get_handle
    handle = open(
             ^^^^^
FileNotFoundError: [Errno 2] No such file or directory: 'online_retail.csv'
[2024-04-11T16:47:49.333+0000] {taskinstance.py:1205} INFO - Marking task as UP_FOR_RETRY. dag_id=22655381_DAG2, task_id=process_data, execution_date=20240411T164600, start_date=20240411T164749, end_date=20240411T164749
[2024-04-11T16:47:49.339+0000] {standard_task_runner.py:110} ERROR - Failed to execute job 4 for task process_data ([Errno 2] No such file or directory: 'online_retail.csv'; 1782)
[2024-04-11T16:47:49.352+0000] {local_task_job_runner.py:240} INFO - Task exited with return code 1
[2024-04-11T16:47:49.363+0000] {taskinstance.py:3482} INFO - 0 downstream tasks scheduled from follow-on schedule check
[2024-04-11T16:47:49.364+0000] {local_task_job_runner.py:222} INFO - ::endgroup::
