[2024-04-11T16:54:47.392+0000] {local_task_job_runner.py:120} INFO - ::group::Pre task execution logs
[2024-04-11T16:54:47.518+0000] {taskinstance.py:2073} INFO - Dependencies all met for dep_context=non-requeueable deps ti=<TaskInstance: 22655381_DAG2_v01.insert_data scheduled__2024-04-11T16:50:00+00:00 [queued]>
[2024-04-11T16:54:47.541+0000] {taskinstance.py:2073} INFO - Dependencies all met for dep_context=requeueable deps ti=<TaskInstance: 22655381_DAG2_v01.insert_data scheduled__2024-04-11T16:50:00+00:00 [queued]>
[2024-04-11T16:54:47.543+0000] {taskinstance.py:2303} INFO - Starting attempt 2 of 3
[2024-04-11T16:54:47.663+0000] {taskinstance.py:2327} INFO - Executing <Task(PostgresOperator): insert_data> on 2024-04-11 16:50:00+00:00
[2024-04-11T16:54:47.733+0000] {logging_mixin.py:188} WARNING - /home/***/.local/lib/python3.12/site-packages/***/task/task_runner/standard_task_runner.py:61 DeprecationWarning: This process (pid=2478) is multi-threaded, use of fork() may lead to deadlocks in the child.
[2024-04-11T16:54:47.737+0000] {standard_task_runner.py:63} INFO - Started process 2498 to run task
[2024-04-11T16:54:47.735+0000] {standard_task_runner.py:90} INFO - Running: ['***', 'tasks', 'run', '22655381_DAG2_v01', 'insert_data', 'scheduled__2024-04-11T16:50:00+00:00', '--job-id', '53', '--raw', '--subdir', 'DAGS_FOLDER/dag_exercise.py', '--cfg-path', '/tmp/tmp41tu_hfg']
[2024-04-11T16:54:47.743+0000] {standard_task_runner.py:91} INFO - Job 53: Subtask insert_data
[2024-04-11T16:54:47.901+0000] {task_command.py:426} INFO - Running <TaskInstance: 22655381_DAG2_v01.insert_data scheduled__2024-04-11T16:50:00+00:00 [running]> on host 51938eebcb2b
[2024-04-11T16:54:48.063+0000] {taskinstance.py:2644} INFO - Exporting env vars: AIRFLOW_CTX_DAG_OWNER='Le Van Duy' AIRFLOW_CTX_DAG_ID='22655381_DAG2_v01' AIRFLOW_CTX_TASK_ID='insert_data' AIRFLOW_CTX_EXECUTION_DATE='2024-04-11T16:50:00+00:00' AIRFLOW_CTX_TRY_NUMBER='2' AIRFLOW_CTX_DAG_RUN_ID='scheduled__2024-04-11T16:50:00+00:00'
[2024-04-11T16:54:48.072+0000] {taskinstance.py:430} INFO - ::endgroup::
[2024-04-11T16:54:48.073+0000] {sql.py:276} INFO - Executing: COPY online_retail FROM '/opt/***/include/dataset/processed_online_retail.csv' DELIMITER ',' CSV HEADER
[2024-04-11T16:54:48.087+0000] {base.py:84} INFO - Using connection ID 'postgres_localhost' for task execution.
[2024-04-11T16:54:48.113+0000] {base.py:84} INFO - Using connection ID 'postgres_localhost' for task execution.
[2024-04-11T16:54:48.134+0000] {sql.py:457} INFO - Running statement: COPY online_retail FROM '/opt/***/include/dataset/processed_online_retail.csv' DELIMITER ',' CSV HEADER, parameters: None
[2024-04-11T16:54:48.138+0000] {taskinstance.py:441} INFO - ::group::Post task execution logs
[2024-04-11T16:54:48.139+0000] {taskinstance.py:2890} ERROR - Task failed with exception
Traceback (most recent call last):
  File "/home/airflow/.local/lib/python3.12/site-packages/airflow/models/taskinstance.py", line 465, in _execute_task
    result = _execute_callable(context=context, **execute_callable_kwargs)
             ^^^^^^^^^^^^^^^^^^^^^^^^^^^^^^^^^^^^^^^^^^^^^^^^^^^^^^^^^^^^^
  File "/home/airflow/.local/lib/python3.12/site-packages/airflow/models/taskinstance.py", line 432, in _execute_callable
    return execute_callable(context=context, **execute_callable_kwargs)
           ^^^^^^^^^^^^^^^^^^^^^^^^^^^^^^^^^^^^^^^^^^^^^^^^^^^^^^^^^^^^
  File "/home/airflow/.local/lib/python3.12/site-packages/airflow/models/baseoperator.py", line 400, in wrapper
    return func(self, *args, **kwargs)
           ^^^^^^^^^^^^^^^^^^^^^^^^^^^
  File "/home/airflow/.local/lib/python3.12/site-packages/airflow/providers/common/sql/operators/sql.py", line 282, in execute
    output = hook.run(
             ^^^^^^^^^
  File "/home/airflow/.local/lib/python3.12/site-packages/airflow/providers/common/sql/hooks/sql.py", line 404, in run
    self._run_command(cur, sql_statement, parameters)
  File "/home/airflow/.local/lib/python3.12/site-packages/airflow/providers/common/sql/hooks/sql.py", line 462, in _run_command
    cur.execute(sql_statement)
psycopg2.errors.UndefinedFile: could not open file "/opt/***/include/dataset/processed_online_retail.csv" for reading: No such file or directory
HINT:  COPY FROM instructs the PostgreSQL server process to read a file. You may want a client-side facility such as psql's \copy.

[2024-04-11T16:54:48.150+0000] {taskinstance.py:1205} INFO - Marking task as UP_FOR_RETRY. dag_id=22655381_DAG2_v01, task_id=insert_data, execution_date=20240411T165000, start_date=20240411T165447, end_date=20240411T165448
[2024-04-11T16:54:48.169+0000] {standard_task_runner.py:110} ERROR - Failed to execute job 53 for task insert_data (could not open file "/opt/***/include/dataset/processed_online_retail.csv" for reading: No such file or directory
HINT:  COPY FROM instructs the PostgreSQL server process to read a file. You may want a client-side facility such as psql's \copy.
; 2498)
[2024-04-11T16:54:48.231+0000] {local_task_job_runner.py:240} INFO - Task exited with return code 1
[2024-04-11T16:54:48.275+0000] {taskinstance.py:3482} INFO - 0 downstream tasks scheduled from follow-on schedule check
[2024-04-11T16:54:48.279+0000] {local_task_job_runner.py:222} INFO - ::endgroup::
