[2024-04-11T15:36:50.191+0000] {task_context_logger.py:104} ERROR - Executor reports task instance <TaskInstance: dag_with_gg_bigquery_v06.first_query scheduled__2024-04-09T17:00:00+00:00 [queued]> finished (success) although the task says it's queued. (Info: None) Was the task killed externally?
