[2024-04-11T15:19:20.082+0000] {local_task_job_runner.py:120} INFO - ::group::Pre task execution logs
[2024-04-11T15:19:20.091+0000] {taskinstance.py:2073} INFO - Dependencies all met for dep_context=non-requeueable deps ti=<TaskInstance: dag_with_gg_bigquery_v05.fetch_query_result scheduled__2024-04-09T17:00:00+00:00 [queued]>
[2024-04-11T15:19:20.096+0000] {taskinstance.py:2073} INFO - Dependencies all met for dep_context=requeueable deps ti=<TaskInstance: dag_with_gg_bigquery_v05.fetch_query_result scheduled__2024-04-09T17:00:00+00:00 [queued]>
[2024-04-11T15:19:20.096+0000] {taskinstance.py:2303} INFO - Starting attempt 1 of 2
[2024-04-11T15:19:20.101+0000] {taskinstance.py:2327} INFO - Executing <Task(PythonOperator): fetch_query_result> on 2024-04-09 17:00:00+00:00
[2024-04-11T15:19:20.107+0000] {logging_mixin.py:188} WARNING - /home/***/.local/lib/python3.12/site-packages/***/task/task_runner/standard_task_runner.py:61 DeprecationWarning: This process (pid=5547) is multi-threaded, use of fork() may lead to deadlocks in the child.
[2024-04-11T15:19:20.108+0000] {standard_task_runner.py:63} INFO - Started process 5549 to run task
[2024-04-11T15:19:20.108+0000] {standard_task_runner.py:90} INFO - Running: ['***', 'tasks', 'run', 'dag_with_gg_bigquery_v05', 'fetch_query_result', 'scheduled__2024-04-09T17:00:00+00:00', '--job-id', '41', '--raw', '--subdir', 'DAGS_FOLDER/dag_with_gg_bigquery.py', '--cfg-path', '/tmp/tmp8bq96gjq']
[2024-04-11T15:19:20.110+0000] {standard_task_runner.py:91} INFO - Job 41: Subtask fetch_query_result
[2024-04-11T15:19:20.137+0000] {task_command.py:426} INFO - Running <TaskInstance: dag_with_gg_bigquery_v05.fetch_query_result scheduled__2024-04-09T17:00:00+00:00 [running]> on host a4f2bd86ee13
[2024-04-11T15:19:20.175+0000] {taskinstance.py:2644} INFO - Exporting env vars: AIRFLOW_CTX_DAG_OWNER='duy' AIRFLOW_CTX_DAG_ID='dag_with_gg_bigquery_v05' AIRFLOW_CTX_TASK_ID='fetch_query_result' AIRFLOW_CTX_EXECUTION_DATE='2024-04-09T17:00:00+00:00' AIRFLOW_CTX_TRY_NUMBER='1' AIRFLOW_CTX_DAG_RUN_ID='scheduled__2024-04-09T17:00:00+00:00'
[2024-04-11T15:19:20.175+0000] {taskinstance.py:430} INFO - ::endgroup::
[2024-04-11T15:19:20.187+0000] {connection.py:274} WARNING - Connection schemes (type: google_cloud_platform) shall not contain '_' according to RFC3986.
[2024-04-11T15:19:20.187+0000] {base.py:84} INFO - Using connection ID 'gcp' for task execution.
[2024-04-11T15:19:20.188+0000] {taskinstance.py:441} INFO - ::group::Post task execution logs
[2024-04-11T15:19:20.191+0000] {taskinstance.py:2890} ERROR - Task failed with exception
Traceback (most recent call last):
  File "/home/airflow/.local/lib/python3.12/site-packages/airflow/models/taskinstance.py", line 465, in _execute_task
    result = _execute_callable(context=context, **execute_callable_kwargs)
             ^^^^^^^^^^^^^^^^^^^^^^^^^^^^^^^^^^^^^^^^^^^^^^^^^^^^^^^^^^^^^
  File "/home/airflow/.local/lib/python3.12/site-packages/airflow/models/taskinstance.py", line 432, in _execute_callable
    return execute_callable(context=context, **execute_callable_kwargs)
           ^^^^^^^^^^^^^^^^^^^^^^^^^^^^^^^^^^^^^^^^^^^^^^^^^^^^^^^^^^^^
  File "/home/airflow/.local/lib/python3.12/site-packages/airflow/models/baseoperator.py", line 400, in wrapper
    return func(self, *args, **kwargs)
           ^^^^^^^^^^^^^^^^^^^^^^^^^^^
  File "/home/airflow/.local/lib/python3.12/site-packages/airflow/operators/python.py", line 235, in execute
    return_value = self.execute_callable()
                   ^^^^^^^^^^^^^^^^^^^^^^^
  File "/home/airflow/.local/lib/python3.12/site-packages/airflow/operators/python.py", line 252, in execute_callable
    return self.python_callable(*self.op_args, **self.op_kwargs)
           ^^^^^^^^^^^^^^^^^^^^^^^^^^^^^^^^^^^^^^^^^^^^^^^^^^^^^
  File "/opt/airflow/dags/dag_with_gg_bigquery.py", line 59, in fetch_query_result
    result = hook.get_records(sql)
             ^^^^^^^^^^^^^^^^^^^^^
  File "/home/airflow/.local/lib/python3.12/site-packages/airflow/providers/google/cloud/hooks/bigquery.py", line 200, in get_records
    raise AirflowException("Need to specify 'location' to use BigQueryHook.get_records()")
airflow.exceptions.AirflowException: Need to specify 'location' to use BigQueryHook.get_records()
[2024-04-11T15:19:20.196+0000] {taskinstance.py:1205} INFO - Marking task as UP_FOR_RETRY. dag_id=dag_with_gg_bigquery_v05, task_id=fetch_query_result, execution_date=20240409T170000, start_date=20240411T151920, end_date=20240411T151920
[2024-04-11T15:19:20.204+0000] {standard_task_runner.py:110} ERROR - Failed to execute job 41 for task fetch_query_result (Need to specify 'location' to use BigQueryHook.get_records(); 5549)
[2024-04-11T15:19:20.212+0000] {local_task_job_runner.py:240} INFO - Task exited with return code 1
[2024-04-11T15:19:20.222+0000] {taskinstance.py:3482} INFO - 0 downstream tasks scheduled from follow-on schedule check
[2024-04-11T15:19:20.223+0000] {local_task_job_runner.py:222} INFO - ::endgroup::
