[2024-04-11T17:13:34.409+0000] {local_task_job_runner.py:120} INFO - ::group::Pre task execution logs
[2024-04-11T17:13:34.426+0000] {taskinstance.py:2073} INFO - Dependencies all met for dep_context=non-requeueable deps ti=<TaskInstance: 22655381_DAG2_v02.insert_data scheduled__2024-04-10T17:00:00+00:00 [queued]>
[2024-04-11T17:13:34.431+0000] {taskinstance.py:2073} INFO - Dependencies all met for dep_context=requeueable deps ti=<TaskInstance: 22655381_DAG2_v02.insert_data scheduled__2024-04-10T17:00:00+00:00 [queued]>
[2024-04-11T17:13:34.431+0000] {taskinstance.py:2303} INFO - Starting attempt 7 of 7
[2024-04-11T17:13:34.437+0000] {taskinstance.py:2327} INFO - Executing <Task(PostgresOperator): insert_data> on 2024-04-10 17:00:00+00:00
[2024-04-11T17:13:34.446+0000] {logging_mixin.py:188} WARNING - /home/***/.local/lib/python3.12/site-packages/***/task/task_runner/standard_task_runner.py:61 DeprecationWarning: This process (pid=4050) is multi-threaded, use of fork() may lead to deadlocks in the child.
[2024-04-11T17:13:34.447+0000] {standard_task_runner.py:63} INFO - Started process 4052 to run task
[2024-04-11T17:13:34.447+0000] {standard_task_runner.py:90} INFO - Running: ['***', 'tasks', 'run', '22655381_DAG2_v02', 'insert_data', 'scheduled__2024-04-10T17:00:00+00:00', '--job-id', '101', '--raw', '--subdir', 'DAGS_FOLDER/dag_exercise.py', '--cfg-path', '/tmp/tmph1d5753s']
[2024-04-11T17:13:34.449+0000] {standard_task_runner.py:91} INFO - Job 101: Subtask insert_data
[2024-04-11T17:13:34.500+0000] {task_command.py:426} INFO - Running <TaskInstance: 22655381_DAG2_v02.insert_data scheduled__2024-04-10T17:00:00+00:00 [running]> on host 51938eebcb2b
[2024-04-11T17:13:34.564+0000] {taskinstance.py:2644} INFO - Exporting env vars: AIRFLOW_CTX_DAG_OWNER='Le Van Duy' AIRFLOW_CTX_DAG_ID='22655381_DAG2_v02' AIRFLOW_CTX_TASK_ID='insert_data' AIRFLOW_CTX_EXECUTION_DATE='2024-04-10T17:00:00+00:00' AIRFLOW_CTX_TRY_NUMBER='7' AIRFLOW_CTX_DAG_RUN_ID='scheduled__2024-04-10T17:00:00+00:00'
[2024-04-11T17:13:34.565+0000] {taskinstance.py:430} INFO - ::endgroup::
[2024-04-11T17:13:34.565+0000] {sql.py:276} INFO - Executing: 
            COPY online_retail FROM '/opt/***/include/dataset/online_retail.csv' DELIMITER ',' CSV HEADER
        
[2024-04-11T17:13:34.571+0000] {base.py:84} INFO - Using connection ID 'postgres_localhost' for task execution.
[2024-04-11T17:13:34.577+0000] {base.py:84} INFO - Using connection ID 'postgres_localhost' for task execution.
[2024-04-11T17:13:34.585+0000] {sql.py:457} INFO - Running statement: 
            COPY online_retail FROM '/opt/***/include/dataset/online_retail.csv' DELIMITER ',' CSV HEADER
        , parameters: None
[2024-04-11T17:13:34.586+0000] {taskinstance.py:441} INFO - ::group::Post task execution logs
[2024-04-11T17:13:34.587+0000] {taskinstance.py:2890} ERROR - Task failed with exception
Traceback (most recent call last):
  File "/home/airflow/.local/lib/python3.12/site-packages/airflow/models/taskinstance.py", line 465, in _execute_task
    result = _execute_callable(context=context, **execute_callable_kwargs)
             ^^^^^^^^^^^^^^^^^^^^^^^^^^^^^^^^^^^^^^^^^^^^^^^^^^^^^^^^^^^^^
  File "/home/airflow/.local/lib/python3.12/site-packages/airflow/models/taskinstance.py", line 432, in _execute_callable
    return execute_callable(context=context, **execute_callable_kwargs)
           ^^^^^^^^^^^^^^^^^^^^^^^^^^^^^^^^^^^^^^^^^^^^^^^^^^^^^^^^^^^^
  File "/home/airflow/.local/lib/python3.12/site-packages/airflow/models/baseoperator.py", line 400, in wrapper
    return func(self, *args, **kwargs)
           ^^^^^^^^^^^^^^^^^^^^^^^^^^^
  File "/home/airflow/.local/lib/python3.12/site-packages/airflow/providers/common/sql/operators/sql.py", line 282, in execute
    output = hook.run(
             ^^^^^^^^^
  File "/home/airflow/.local/lib/python3.12/site-packages/airflow/providers/common/sql/hooks/sql.py", line 404, in run
    self._run_command(cur, sql_statement, parameters)
  File "/home/airflow/.local/lib/python3.12/site-packages/airflow/providers/common/sql/hooks/sql.py", line 462, in _run_command
    cur.execute(sql_statement)
psycopg2.errors.UndefinedFile: could not open file "/opt/***/include/dataset/online_retail.csv" for reading: No such file or directory
HINT:  COPY FROM instructs the PostgreSQL server process to read a file. You may want a client-side facility such as psql's \copy.

[2024-04-11T17:13:34.594+0000] {taskinstance.py:1205} INFO - Marking task as FAILED. dag_id=22655381_DAG2_v02, task_id=insert_data, execution_date=20240410T170000, start_date=20240411T171334, end_date=20240411T171334
[2024-04-11T17:13:34.600+0000] {standard_task_runner.py:110} ERROR - Failed to execute job 101 for task insert_data (could not open file "/opt/***/include/dataset/online_retail.csv" for reading: No such file or directory
HINT:  COPY FROM instructs the PostgreSQL server process to read a file. You may want a client-side facility such as psql's \copy.
; 4052)
[2024-04-11T17:13:34.630+0000] {local_task_job_runner.py:240} INFO - Task exited with return code 1
[2024-04-11T17:13:34.647+0000] {taskinstance.py:3482} INFO - 0 downstream tasks scheduled from follow-on schedule check
[2024-04-11T17:13:34.648+0000] {local_task_job_runner.py:222} INFO - ::endgroup::
