[2024-04-11T17:08:39.670+0000] {local_task_job_runner.py:120} INFO - ::group::Pre task execution logs
[2024-04-11T17:08:39.686+0000] {taskinstance.py:2073} INFO - Dependencies all met for dep_context=non-requeueable deps ti=<TaskInstance: 22655381_DAG2_v02.save_data scheduled__2024-04-10T17:00:00+00:00 [queued]>
[2024-04-11T17:08:39.689+0000] {taskinstance.py:2073} INFO - Dependencies all met for dep_context=requeueable deps ti=<TaskInstance: 22655381_DAG2_v02.save_data scheduled__2024-04-10T17:00:00+00:00 [queued]>
[2024-04-11T17:08:39.690+0000] {taskinstance.py:2303} INFO - Starting attempt 4 of 5
[2024-04-11T17:08:39.696+0000] {taskinstance.py:2327} INFO - Executing <Task(PythonOperator): save_data> on 2024-04-10 17:00:00+00:00
[2024-04-11T17:08:39.704+0000] {logging_mixin.py:188} WARNING - /home/***/.local/lib/python3.12/site-packages/***/task/task_runner/standard_task_runner.py:61 DeprecationWarning: This process (pid=3661) is multi-threaded, use of fork() may lead to deadlocks in the child.
[2024-04-11T17:08:39.706+0000] {standard_task_runner.py:63} INFO - Started process 3668 to run task
[2024-04-11T17:08:39.708+0000] {standard_task_runner.py:90} INFO - Running: ['***', 'tasks', 'run', '22655381_DAG2_v02', 'save_data', 'scheduled__2024-04-10T17:00:00+00:00', '--job-id', '93', '--raw', '--subdir', 'DAGS_FOLDER/dag_exercise.py', '--cfg-path', '/tmp/tmp0m7st86p']
[2024-04-11T17:08:39.712+0000] {standard_task_runner.py:91} INFO - Job 93: Subtask save_data
[2024-04-11T17:08:39.741+0000] {task_command.py:426} INFO - Running <TaskInstance: 22655381_DAG2_v02.save_data scheduled__2024-04-10T17:00:00+00:00 [running]> on host 51938eebcb2b
[2024-04-11T17:08:39.779+0000] {taskinstance.py:2644} INFO - Exporting env vars: AIRFLOW_CTX_DAG_OWNER='Le Van Duy' AIRFLOW_CTX_DAG_ID='22655381_DAG2_v02' AIRFLOW_CTX_TASK_ID='save_data' AIRFLOW_CTX_EXECUTION_DATE='2024-04-10T17:00:00+00:00' AIRFLOW_CTX_TRY_NUMBER='4' AIRFLOW_CTX_DAG_RUN_ID='scheduled__2024-04-10T17:00:00+00:00'
[2024-04-11T17:08:39.780+0000] {taskinstance.py:430} INFO - ::endgroup::
[2024-04-11T17:08:40.403+0000] {taskinstance.py:441} INFO - ::group::Post task execution logs
[2024-04-11T17:08:40.403+0000] {taskinstance.py:2890} ERROR - Task failed with exception
Traceback (most recent call last):
  File "/home/airflow/.local/lib/python3.12/site-packages/airflow/models/taskinstance.py", line 465, in _execute_task
    result = _execute_callable(context=context, **execute_callable_kwargs)
             ^^^^^^^^^^^^^^^^^^^^^^^^^^^^^^^^^^^^^^^^^^^^^^^^^^^^^^^^^^^^^
  File "/home/airflow/.local/lib/python3.12/site-packages/airflow/models/taskinstance.py", line 432, in _execute_callable
    return execute_callable(context=context, **execute_callable_kwargs)
           ^^^^^^^^^^^^^^^^^^^^^^^^^^^^^^^^^^^^^^^^^^^^^^^^^^^^^^^^^^^^
  File "/home/airflow/.local/lib/python3.12/site-packages/airflow/models/baseoperator.py", line 400, in wrapper
    return func(self, *args, **kwargs)
           ^^^^^^^^^^^^^^^^^^^^^^^^^^^
  File "/home/airflow/.local/lib/python3.12/site-packages/airflow/operators/python.py", line 235, in execute
    return_value = self.execute_callable()
                   ^^^^^^^^^^^^^^^^^^^^^^^
  File "/home/airflow/.local/lib/python3.12/site-packages/airflow/operators/python.py", line 252, in execute_callable
    return self.python_callable(*self.op_args, **self.op_kwargs)
           ^^^^^^^^^^^^^^^^^^^^^^^^^^^^^^^^^^^^^^^^^^^^^^^^^^^^^
  File "/opt/airflow/dags/dag_exercise.py", line 41, in save_data
    df.to_csv('data/dataprocessed_online_retail.csv', index=False)
  File "/home/airflow/.local/lib/python3.12/site-packages/pandas/core/generic.py", line 3902, in to_csv
    return DataFrameRenderer(formatter).to_csv(
           ^^^^^^^^^^^^^^^^^^^^^^^^^^^^^^^^^^^^
  File "/home/airflow/.local/lib/python3.12/site-packages/pandas/io/formats/format.py", line 1152, in to_csv
    csv_formatter.save()
  File "/home/airflow/.local/lib/python3.12/site-packages/pandas/io/formats/csvs.py", line 247, in save
    with get_handle(
         ^^^^^^^^^^^
  File "/home/airflow/.local/lib/python3.12/site-packages/pandas/io/common.py", line 739, in get_handle
    check_parent_directory(str(handle))
  File "/home/airflow/.local/lib/python3.12/site-packages/pandas/io/common.py", line 604, in check_parent_directory
    raise OSError(rf"Cannot save file into a non-existent directory: '{parent}'")
OSError: Cannot save file into a non-existent directory: 'data'
[2024-04-11T17:08:40.416+0000] {taskinstance.py:1205} INFO - Marking task as UP_FOR_RETRY. dag_id=22655381_DAG2_v02, task_id=save_data, execution_date=20240410T170000, start_date=20240411T170839, end_date=20240411T170840
[2024-04-11T17:08:40.422+0000] {standard_task_runner.py:110} ERROR - Failed to execute job 93 for task save_data (Cannot save file into a non-existent directory: 'data'; 3668)
[2024-04-11T17:08:40.463+0000] {local_task_job_runner.py:240} INFO - Task exited with return code 1
[2024-04-11T17:08:40.471+0000] {logging_mixin.py:188} WARNING - /home/***/.local/lib/python3.12/site-packages/***/models/baseoperator.py:1296 AirflowProviderDeprecationWarning: Call to deprecated class PostgresOperator. (Please use `***.providers.common.sql.operators.sql.SQLExecuteQueryOperator`.Also, you can provide `hook_params={'schema': <database>}`.)
[2024-04-11T17:08:40.478+0000] {taskinstance.py:3482} INFO - 0 downstream tasks scheduled from follow-on schedule check
[2024-04-11T17:08:40.479+0000] {local_task_job_runner.py:222} INFO - ::endgroup::
