[2024-04-11T17:51:44.662+0000] {local_task_job_runner.py:120} INFO - ::group::Pre task execution logs
[2024-04-11T17:51:44.677+0000] {taskinstance.py:2073} INFO - Dependencies all met for dep_context=non-requeueable deps ti=<TaskInstance: dag_with_gg_bigquery_v07.upload_csv_to_gcs scheduled__2024-04-10T17:00:00+00:00 [queued]>
[2024-04-11T17:51:44.682+0000] {taskinstance.py:2073} INFO - Dependencies all met for dep_context=requeueable deps ti=<TaskInstance: dag_with_gg_bigquery_v07.upload_csv_to_gcs scheduled__2024-04-10T17:00:00+00:00 [queued]>
[2024-04-11T17:51:44.682+0000] {taskinstance.py:2303} INFO - Starting attempt 1 of 2
[2024-04-11T17:51:44.690+0000] {taskinstance.py:2327} INFO - Executing <Task(LocalFilesystemToGCSOperator): upload_csv_to_gcs> on 2024-04-10 17:00:00+00:00
[2024-04-11T17:51:44.697+0000] {logging_mixin.py:188} WARNING - /home/***/.local/lib/python3.12/site-packages/***/task/task_runner/standard_task_runner.py:61 DeprecationWarning: This process (pid=703) is multi-threaded, use of fork() may lead to deadlocks in the child.
[2024-04-11T17:51:44.696+0000] {standard_task_runner.py:90} INFO - Running: ['***', 'tasks', 'run', 'dag_with_gg_bigquery_v07', 'upload_csv_to_gcs', 'scheduled__2024-04-10T17:00:00+00:00', '--job-id', '172', '--raw', '--subdir', 'DAGS_FOLDER/dag_with_gg_bigquery.py', '--cfg-path', '/tmp/tmpp6pk5fy_']
[2024-04-11T17:51:44.698+0000] {standard_task_runner.py:91} INFO - Job 172: Subtask upload_csv_to_gcs
[2024-04-11T17:51:44.698+0000] {standard_task_runner.py:63} INFO - Started process 705 to run task
[2024-04-11T17:51:44.726+0000] {task_command.py:426} INFO - Running <TaskInstance: dag_with_gg_bigquery_v07.upload_csv_to_gcs scheduled__2024-04-10T17:00:00+00:00 [running]> on host caed5d205145
[2024-04-11T17:51:44.783+0000] {taskinstance.py:2644} INFO - Exporting env vars: AIRFLOW_CTX_DAG_OWNER='duy' AIRFLOW_CTX_DAG_ID='dag_with_gg_bigquery_v07' AIRFLOW_CTX_TASK_ID='upload_csv_to_gcs' AIRFLOW_CTX_EXECUTION_DATE='2024-04-10T17:00:00+00:00' AIRFLOW_CTX_TRY_NUMBER='1' AIRFLOW_CTX_DAG_RUN_ID='scheduled__2024-04-10T17:00:00+00:00'
[2024-04-11T17:51:44.783+0000] {taskinstance.py:430} INFO - ::endgroup::
[2024-04-11T17:51:44.794+0000] {taskinstance.py:441} INFO - ::group::Post task execution logs
[2024-04-11T17:51:44.798+0000] {taskinstance.py:2890} ERROR - Task failed with exception
Traceback (most recent call last):
  File "/home/airflow/.local/lib/python3.12/site-packages/airflow/models/taskinstance.py", line 465, in _execute_task
    result = _execute_callable(context=context, **execute_callable_kwargs)
             ^^^^^^^^^^^^^^^^^^^^^^^^^^^^^^^^^^^^^^^^^^^^^^^^^^^^^^^^^^^^^
  File "/home/airflow/.local/lib/python3.12/site-packages/airflow/models/taskinstance.py", line 432, in _execute_callable
    return execute_callable(context=context, **execute_callable_kwargs)
           ^^^^^^^^^^^^^^^^^^^^^^^^^^^^^^^^^^^^^^^^^^^^^^^^^^^^^^^^^^^^
  File "/home/airflow/.local/lib/python3.12/site-packages/airflow/models/baseoperator.py", line 400, in wrapper
    return func(self, *args, **kwargs)
           ^^^^^^^^^^^^^^^^^^^^^^^^^^^
  File "/home/airflow/.local/lib/python3.12/site-packages/airflow/providers/google/cloud/transfers/local_to_gcs.py", line 90, in execute
    hook = GCSHook(
           ^^^^^^^^
  File "/home/airflow/.local/lib/python3.12/site-packages/airflow/providers/google/cloud/hooks/gcs.py", line 159, in __init__
    super().__init__(
  File "/home/airflow/.local/lib/python3.12/site-packages/airflow/providers/google/common/hooks/base_google.py", line 251, in __init__
    self.extras: dict = self.get_connection(self.gcp_conn_id).extra_dejson
                        ^^^^^^^^^^^^^^^^^^^^^^^^^^^^^^^^^^^^^
  File "/home/airflow/.local/lib/python3.12/site-packages/airflow/hooks/base.py", line 83, in get_connection
    conn = Connection.get_connection_from_secrets(conn_id)
           ^^^^^^^^^^^^^^^^^^^^^^^^^^^^^^^^^^^^^^^^^^^^^^^
  File "/home/airflow/.local/lib/python3.12/site-packages/airflow/models/connection.py", line 519, in get_connection_from_secrets
    raise AirflowNotFoundException(f"The conn_id `{conn_id}` isn't defined")
airflow.exceptions.AirflowNotFoundException: The conn_id `gcp` isn't defined
[2024-04-11T17:51:44.802+0000] {taskinstance.py:1205} INFO - Marking task as UP_FOR_RETRY. dag_id=dag_with_gg_bigquery_v07, task_id=upload_csv_to_gcs, execution_date=20240410T170000, start_date=20240411T175144, end_date=20240411T175144
[2024-04-11T17:51:44.807+0000] {standard_task_runner.py:110} ERROR - Failed to execute job 172 for task upload_csv_to_gcs (The conn_id `gcp` isn't defined; 705)
[2024-04-11T17:51:44.843+0000] {local_task_job_runner.py:240} INFO - Task exited with return code 1
[2024-04-11T17:51:44.849+0000] {logging_mixin.py:188} WARNING - /home/***/.local/lib/python3.12/site-packages/***/models/baseoperator.py:1296 AirflowProviderDeprecationWarning: Call to deprecated class BigQueryExecuteQueryOperator. (This operator is deprecated. Please use `BigQueryInsertJobOperator`.)
[2024-04-11T17:51:44.856+0000] {taskinstance.py:3482} INFO - 0 downstream tasks scheduled from follow-on schedule check
[2024-04-11T17:51:44.856+0000] {local_task_job_runner.py:222} INFO - ::endgroup::
