[2024-04-11T16:51:02.095+0000] {task_context_logger.py:104} ERROR - Executor reports task instance <TaskInstance: 22655381_DAG2.create_table scheduled__2024-04-11T16:50:00+00:00 [queued]> finished (success) although the task says it's queued. (Info: None) Was the task killed externally?
